Workbook

Sheet Table 1
A1: Ruhan 20 Pay | H1: Ruhan 10 Pay | O1: Ruhan L65
A2: Yr | B2: Age | C2: Annual Premium | D2: Cum Outlay | E2: Cash Value | F2: Death Benefit | G2: Outlay to Cash Value % | H2: Yr | I2: Age | J2: Annual Premium | K2: Cum Outlay | L2: Cash Value | M2: Death Benefit | N2: Outlay to Cash Value % | O2: Yr | P2: Age | Q2: Annual Premium | R2: Cum Outlay | S2: Cash Value | T2: Death Benefit | U2: Outlay to Cash Value %
A3: 1 | B3: 5 | C3: =Sheet2!C1 -> 2500 | D3: =C3 -> 2500 | E3: =Sheet2!G1 -> 294 | F3: =Sheet2!H1 -> 220095 | G3: =E3/D3 -> 0.1176 | H3: 1 | I3: =B3 -> 5 | J3: =Sheet2!X1 -> 3280 | K3: =J3 -> 3280 | L3: =Sheet2!AA1 -> 1183 | M3: =Sheet2!AB1 -> 100402 | N3: =L3/K3 -> 0.36067073 | O3: 1 | P3: =I3 -> 5 | Q3: =Sheet2!AG1 -> 2500 | R3: =Q3 -> 2500 | S3: =Sheet2!AJ1 -> 1310 | T3: =Sheet2!AK1 -> 180186 | U3: =S3/R3 -> 0.524
A4: 2 | B4: =B3+1 -> 6 | C4: =Sheet2!C2 -> 2500 | D4: =SUM($C$3:C4) -> 5000 | E4: =Sheet2!G2 -> 759 | F4: =Sheet2!H2 -> 222407 | G4: =E4/D4 -> 0.1518 | H4: 2 | I4: =I3+1 -> 6 | J4: =Sheet2!X2 -> 3280 | K4: =K3+J4 -> 6560 | L4: =Sheet2!AA2 -> 3263 | M4: =Sheet2!AB2 -> 101122 | N4: =L4/K4 -> 0.49740854 | O4: 2 | P4: =P3+1 -> 6 | Q4: =Sheet2!AG2 -> 2500 | R4: =R3+Q4 -> 5000 | S4: =Sheet2!AJ2 -> 2852 | T4: =Sheet2!AK2 -> 190771 | U4: =S4/R4 -> 0.5704
A5: 3 | B5: =B4+1 -> 7 | C5: =Sheet2!C3 -> 2500 | D5: =SUM($C$3:C5) -> 7500 | E5: =Sheet2!G3 -> 3083 | F5: =Sheet2!H3 -> 224855 | G5: =E5/D5 -> 0.41106667 | H5: 3 | I5: =I4+1 -> 7 | J5: =Sheet2!X3 -> 3280 | K5: =K4+J5 -> 9840 | L5: =Sheet2!AA3 -> 6496 | M5: =Sheet2!AB3 -> 102170 | N5: =L5/K5 -> 0.6601626 | O5: 3 | P5: =P4+1 -> 7 | Q5: =Sheet2!AG3 -> 2500 | R5: =R4+Q5 -> 7500 | S5: =Sheet2!AJ3 -> 5119 | T5: =Sheet2!AK3 -> 201366 | U5: =S5/R5 -> 0.68253333
A6: 4 | B6: =B5+1 -> 8 | C6: =Sheet2!C4 -> 2500 | D6: =SUM($C$3:C6) -> 10000 | E6: =Sheet2!G4 -> 5499 | F6: =Sheet2!H4 -> 227386 | G6: =E6/D6 -> 0.5499 | H6: 4 | I6: =I5+1 -> 8 | J6: =Sheet2!X4 -> 3280 | K6: =K5+J6 -> 13120 | L6: =Sheet2!AA4 -> 9883 | M6: =Sheet2!AB4 -> 103554 | N6: =L6/K6 -> 0.75327744 | O6: 4 | P6: =P5+1 -> 8 | Q6: =Sheet2!AG4 -> 2500 | R6: =R5+Q6 -> 10000 | S6: =Sheet2!AJ4 -> 7491 | T6: =Sheet2!AK4 -> 211958 | U6: =S6/R6 -> 0.7491
A7: 5 | B7: =B6+1 -> 9 | C7: =Sheet2!C5 -> 2500 | D7: =SUM($C$3:C7) -> 12500 | E7: =Sheet2!G5 -> 8012 | F7: =Sheet2!H5 -> 230015 | G7: =E7/D7 -> 0.64096 | H7: 5 | I7: =I6+1 -> 9 | J7: =Sheet2!X5 -> 3280 | K7: =K6+J7 -> 16400 | L7: =Sheet2!AA5 -> 13433 | M7: =Sheet2!AB5 -> 105275 | N7: =L7/K7 -> 0.81908537 | O7: 5 | P7: =P6+1 -> 9 | Q7: =Sheet2!AG5 -> 2500 | R7: =R6+Q7 -> 12500 | S7: =Sheet2!AJ5 -> 9978 | T7: =Sheet2!AK5 -> 222540 | U7: =S7/R7 -> 0.79824
A8: 6 | B8: =B7+1 -> 10 | C8: =Sheet2!C6 -> 2500 | D8: =SUM($C$3:C8) -> 15000 | E8: =Sheet2!G6 -> 10628 | F8: =Sheet2!H6 -> 232768 | G8: =E8/D8 -> 0.70853333 | H8: 6 | I8: =I7+1 -> 10 | J8: =Sheet2!X6 -> 3280 | K8: =K7+J8 -> 19680 | L8: =Sheet2!AA6 -> 17181 | M8: =Sheet2!AB6 -> 107444 | N8: =L8/K8 -> 0.87301829 | O8: 6 | P8: =P7+1 -> 10 | Q8: =Sheet2!AG6 -> 2500 | R8: =R7+Q8 -> 15000 | S8: =Sheet2!AJ6 -> 12586 | T8: =Sheet2!AK6 -> 233160 | U8: =S8/R8 -> 0.83906667
A9: 7 | B9: =B8+1 -> 11 | C9: =Sheet2!C7 -> 2500 | D9: =SUM($C$3:C9) -> 17500 | E9: =Sheet2!G7 -> 13398 | F9: =Sheet2!H7 -> 235954 | G9: =E9/D9 -> 0.7656 | H9: 7 | I9: =I8+1 -> 11 | J9: =Sheet2!X7 -> 3280 | K9: =K8+J9 -> 22960 | L9: =Sheet2!AA7 -> 21136 | M9: =Sheet2!AB7 -> 110068 | N9: =L9/K9 -> 0.92055749 | O9: 7 | P9: =P8+1 -> 11 | Q9: =Sheet2!AG7 -> 2500 | R9: =R8+Q9 -> 17500 | S9: =Sheet2!AJ7 -> 15323 | T9: =Sheet2!AK7 -> 243824 | U9: =S9/R9 -> 0.8756
A10: 8 | B10: =B9+1 -> 12 | C10: =Sheet2!C8 -> 2500 | D10: =SUM($C$3:C10) -> 20000 | E10: =Sheet2!G8 -> 16327 | F10: =Sheet2!H8 -> 239576 | G10: =E10/D10 -> 0.81635 | H10: 8 | I10: =I9+1 -> 12 | J10: =Sheet2!X8 -> 3280 | K10: =K9+J10 -> 26240 | L10: =Sheet2!AA8 -> 25314 | M10: =Sheet2!AB8 -> 113163 | N10: =L10/K10 -> 0.96471037 | O10: 8 | P10: =P9+1 -> 12 | Q10: =Sheet2!AG8 -> 2500 | R10: =R9+Q10 -> 20000 | S10: =Sheet2!AJ8 -> 18200 | T10: =Sheet2!AK8 -> 254575 | U10: =S10/R10 -> 0.91
A11: 9 | B11: =B10+1 -> 13 | C11: =Sheet2!C9 -> 2500 | D11: =SUM($C$3:C11) -> 22500 | E11: =Sheet2!G9 -> 19423 | F11: =Sheet2!H9 -> 243621 | G11: =E11/D11 -> 0.86324444 | H11: 9 | I11: =I10+1 -> 13 | J11: =Sheet2!X9 -> 3280 | K11: =K10+J11 -> 29520 | L11: =Sheet2!AA9 -> 29721 | M11: =Sheet2!AB9 -> 116727 | N11: =L11/K11 -> 1.0068089 | O11: 9 | P11: =P10+1 -> 13 | Q11: =Sheet2!AG9 -> 2500 | R11: =R10+Q11 -> 22500 | S11: =Sheet2!AJ9 -> 21210 | T11: =Sheet2!AK9 -> 265365 | U11: =S11/R11 -> 0.94266667
A12: 10 | B12: =B11+1 -> 14 | C12: =Sheet2!C10 -> 2500 | D12: =SUM($C$3:C12) -> 25000 | E12: =Sheet2!G10 -> 22691 | F12: =Sheet2!H10 -> 248101 | G12: =E12/D12 -> 0.90764 | H12: 10 | I12: =I11+1 -> 14 | J12: =Sheet2!X10 -> 3280 | K12: =K11+J12 -> 32800 | L12: =Sheet2!AA10 -> 34370 | M12: =Sheet2!AB10 -> 120776 | N12: =L12/K12 -> 1.0478659 | O12: 10 | P12: =P11+1 -> 14 | Q12: =Sheet2!AG10 -> 2500 | R12: =R11+Q12 -> 25000 | S12: =Sheet2!AJ10 -> 24366 | T12: =Sheet2!AK10 -> 276256 | U12: =S12/R12 -> 0.97464
A13: 11 | B13: =B12+1 -> 15 | C13: =Sheet2!C11 -> 2500 | D13: =SUM($C$3:C13) -> 27500 | E13: =Sheet2!G11 -> 26079 | F13: =Sheet2!H11 -> 252706 | G13: =E13/D13 -> 0.94832727 | H13: 11 | I13: =I12+1 -> 15 | K13: =K12+J13 -> 32800 | L13: =Sheet2!AA11 -> 36217 | M13: =Sheet2!AB11 -> 124842 | N13: =L13/K13 -> 1.1041768 | O13: 11 | P13: =P12+1 -> 15 | Q13: =Sheet2!AG11 -> 2500 | R13: =R12+Q13 -> 27500 | S13: =Sheet2!AJ11 -> 27683 | T13: =Sheet2!AK11 -> 287368 | U13: =S13/R13 -> 1.0066545
A14: 12 | B14: =B13+1 -> 16 | C14: =Sheet2!C12 -> 2500 | D14: =SUM($C$3:C14) -> 30000 | E14: =Sheet2!G12 -> 29592 | F14: =Sheet2!H12 -> 257469 | G14: =E14/D14 -> 0.9864 | H14: 12 | I14: =I13+1 -> 16 | K14: =K13+J14 -> 32800 | L14: =Sheet2!AA12 -> 38158 | M14: =Sheet2!AB12 -> 129060 | N14: =L14/K14 -> 1.1633537 | O14: 12 | P14: =P13+1 -> 16 | Q14: =Sheet2!AG12 -> 2500 | R14: =R13+Q14 -> 30000 | S14: =Sheet2!AJ12 -> 31156 | T14: =Sheet2!AK12 -> 298721 | U14: =S14/R14 -> 1.0385333
A15: 13 | B15: =B14+1 -> 17 | C15: =Sheet2!C13 -> 2500 | D15: =SUM($C$3:C15) -> 32500 | E15: =Sheet2!G13 -> 33228 | F15: =Sheet2!H13 -> 262403 | G15: =E15/D15 -> 1.0224 | H15: 13 | I15: =I14+1 -> 17 | K15: =K14+J15 -> 32800 | L15: =Sheet2!AA13 -> 40193 | M15: =Sheet2!AB13 -> 133440 | N15: =L15/K15 -> 1.2253963 | O15: 13 | P15: =P14+1 -> 17 | Q15: =Sheet2!AG13 -> 2500 | R15: =R14+Q15 -> 32500 | S15: =Sheet2!AJ13 -> 34794 | T15: =Sheet2!AK13 -> 310350 | U15: =S15/R15 -> 1.0705846
A16: 14 | B16: =B15+1 -> 18 | C16: =Sheet2!C14 -> 2500 | D16: =SUM($C$3:C16) -> 35000 | E16: =Sheet2!G14 -> 36984 | F16: =Sheet2!H14 -> 267526 | G16: =E16/D16 -> 1.0566857 | H16: 14 | I16: =I15+1 -> 18 | K16: =K15+J16 -> 32800 | L16: =Sheet2!AA14 -> 42329 | M16: =Sheet2!AB14 -> 137992 | N16: =L16/K16 -> 1.2905183 | O16: 14 | P16: =P15+1 -> 18 | Q16: =Sheet2!AG14 -> 2500 | R16: =R15+Q16 -> 35000 | S16: =Sheet2!AJ14 -> 38590 | T16: =Sheet2!AK14 -> 322269 | U16: =S16/R16 -> 1.1025714
A17: 15 | B17: =B16+1 -> 19 | C17: =Sheet2!C15 -> 2500 | D17: =SUM($C$3:C17) -> 37500 | E17: =Sheet2!G15 -> 40889 | F17: =Sheet2!H15 -> 272894 | G17: =E17/D17 -> 1.0903733 | H17: 15 | I17: =I16+1 -> 19 | K17: =K16+J17 -> 32800 | L17: =Sheet2!AA15 -> 44564 | M17: =Sheet2!AB15 -> 142692 | N17: =L17/K17 -> 1.3586585 | O17: 15 | P17: =P16+1 -> 19 | Q17: =Sheet2!AG15 -> 2500 | R17: =R16+Q17 -> 37500 | S17: =Sheet2!AJ15 -> 42565 | T17: =Sheet2!AK15 -> 334500 | U17: =S17/R17 -> 1.1350667
A18: 16 | B18: =B17+1 -> 20 | C18: =Sheet2!C16 -> 2500 | D18: =SUM($C$3:C18) -> 40000 | E18: =Sheet2!G16 -> 45086 | F18: =Sheet2!H16 -> 279105 | G18: =E18/D18 -> 1.12715 | H18: 16 | I18: =I17+1 -> 20 | K18: =K17+J18 -> 32800 | L18: =Sheet2!AA16 -> 46920 | M18: =Sheet2!AB16 -> 147565 | N18: =L18/K18 -> 1.4304878 | O18: 16 | P18: =P17+1 -> 20 | Q18: =Sheet2!AG16 -> 2500 | R18: =R17+Q18 -> 40000 | S18: =Sheet2!AJ16 -> 46777 | T18: =Sheet2!AK16 -> 347123 | U18: =S18/R18 -> 1.169425
A19: 17 | B19: =B18+1 -> 21 | C19: =Sheet2!C17 -> 2500 | D19: =SUM($C$3:C19) -> 42500 | E19: =Sheet2!G17 -> 49577 | F19: =Sheet2!H17 -> 286071 | G19: =E19/D19 -> 1.1665176 | H19: 17 | I19: =I18+1 -> 21 | K19: =K18+J19 -> 32800 | L19: =Sheet2!AA17 -> 49401 | M19: =Sheet2!AB17 -> 152612 | N19: =L19/K19 -> 1.506128 | O19: 17 | P19: =P18+1 -> 21 | Q19: =Sheet2!AG17 -> 2500 | R19: =R18+Q19 -> 42500 | S19: =Sheet2!AJ17 -> 51190 | T19: =Sheet2!AK17 -> 359908 | U19: =S19/R19 -> 1.2044706
A20: 18 | B20: =B19+1 -> 22 | C20: =Sheet2!C18 -> 2500 | D20: =SUM($C$3:C20) -> 45000 | E20: =Sheet2!G18 -> 54371 | F20: =Sheet2!H18 -> 293778 | G20: =E20/D20 -> 1.2082444 | H20: 18 | I20: =I19+1 -> 22 | K20: =K19+J20 -> 32800 | L20: =Sheet2!AA18 -> 52013 | M20: =Sheet2!AB18 -> 157836 | N20: =L20/K20 -> 1.5857622 | O20: 18 | P20: =P19+1 -> 22 | Q20: =Sheet2!AG18 -> 2500 | R20: =R19+Q20 -> 45000 | S20: =Sheet2!AJ18 -> 55816 | T20: =Sheet2!AK18 -> 372868 | U20: =S20/R20 -> 1.2403556
A21: 19 | B21: =B20+1 -> 23 | C21: =Sheet2!C19 -> 2500 | D21: =SUM($C$3:C21) -> 47500 | E21: =Sheet2!G19 -> 59493 | F21: =Sheet2!H19 -> 302237 | G21: =E21/D21 -> 1.2524842 | H21: 19 | I21: =I20+1 -> 23 | K21: =K20+J21 -> 32800 | L21: =Sheet2!AA19 -> 54770 | M21: =Sheet2!AB19 -> 163252 | N21: =L21/K21 -> 1.6698171 | O21: 19 | P21: =P20+1 -> 23 | Q21: =Sheet2!AG19 -> 2500 | R21: =R20+Q21 -> 47500 | S21: =Sheet2!AJ19 -> 60670 | T21: =Sheet2!AK19 -> 386024 | U21: =S21/R21 -> 1.2772632
A22: 20 | B22: =B21+1 -> 24 | C22: =Sheet2!C20 -> 2500 | D22: =SUM($C$3:C22) -> 50000 | E22: =Sheet2!G20 -> 64952 | F22: =Sheet2!H20 -> 311415 | G22: =E22/D22 -> 1.29904 | H22: 20 | I22: =I21+1 -> 24 | K22: =K21+J22 -> 32800 | L22: =Sheet2!AA20 -> 57671 | M22: =Sheet2!AB20 -> 168856 | N22: =L22/K22 -> 1.7582622 | O22: 20 | P22: =P21+1 -> 24 | Q22: =Sheet2!AG20 -> 2500 | R22: =R21+Q22 -> 50000 | S22: =Sheet2!AJ20 -> 65757 | T22: =Sheet2!AK20 -> 399346 | U22: =S22/R22 -> 1.31514
A23: 21 | B23: =B22+1 -> 25 | D23: =SUM($C$3:C23) -> 50000 | E23: =Sheet2!G21 -> 68311 | F23: =Sheet2!H21 -> 319194 | G23: =E23/D23 -> 1.36622 | H23: 21 | I23: =I22+1 -> 25 | K23: =K22+J23 -> 32800 | L23: =Sheet2!AA21 -> 60725 | M23: =Sheet2!AB21 -> 174652 | N23: =L23/K23 -> 1.851372 | O23: 21 | P23: =P22+1 -> 25 | Q23: =Sheet2!AG21 -> 0 | R23: =R22+Q23 -> 50000 | S23: =Sheet2!AJ21 -> 69020 | T23: =Sheet2!AK21 -> 322508 | U23: =S23/R23 -> 1.3804
A24: 22 | B24: =B23+1 -> 26 | D24: =SUM($C$3:C24) -> 50000 | E24: =Sheet2!G22 -> 71845 | F24: =Sheet2!H22 -> 327161 | G24: =E24/D24 -> 1.4369 | H24: 22 | I24: =I23+1 -> 26 | K24: =K23+J24 -> 32800 | L24: =Sheet2!AA22 -> 63943 | M24: =Sheet2!AB22 -> 180652 | N24: =L24/K24 -> 1.9494817 | O24: 22 | P24: =P23+1 -> 26 | Q24: =Sheet2!AG22 -> 0 | R24: =R23+Q24 -> 50000 | S24: =Sheet2!AJ22 -> 72447 | T24: =Sheet2!AK22 -> 329905 | U24: =S24/R24 -> 1.44894
A25: 23 | B25: =B24+1 -> 27 | D25: =SUM($C$3:C25) -> 50000 | E25: =Sheet2!G23 -> 75569 | F25: =Sheet2!H23 -> 335324 | G25: =E25/D25 -> 1.51138 | H25: 23 | I25: =I24+1 -> 27 | K25: =K24+J25 -> 32800 | L25: =Sheet2!AA23 -> 67332 | M25: =Sheet2!AB23 -> 186851 | N25: =L25/K25 -> 2.0528049 | O25: 23 | P25: =P24+1 -> 27 | Q25: =Sheet2!AG23 -> 0 | R25: =R24+Q25 -> 50000 | S25: =Sheet2!AJ23 -> 76052 | T25: =Sheet2!AK23 -> 337467 | U25: =S25/R25 -> 1.52104
A26: 24 | B26: =B25+1 -> 28 | D26: =SUM($C$3:C26) -> 50000 | E26: =Sheet2!G24 -> 79490 | F26: =Sheet2!H24 -> 343650 | G26: =E26/D26 -> 1.5898 | H26: 24 | I26: =I25+1 -> 28 | K26: =K25+J26 -> 32800 | L26: =Sheet2!AA24 -> 70904 | M26: =Sheet2!AB24 -> 193251 | N26: =L26/K26 -> 2.1617073 | O26: 24 | P26: =P25+1 -> 28 | Q26: =Sheet2!AG24 -> 0 | R26: =R25+Q26 -> 50000 | S26: =Sheet2!AJ24 -> 79843 | T26: =Sheet2!AK24 -> 345177 | U26: =S26/R26 -> 1.59686
A27: 25 | B27: =B26+1 -> 29 | D27: =SUM($C$3:C27) -> 50000 | E27: =Sheet2!G25 -> 83629 | F27: =Sheet2!H25 -> 352165 | G27: =E27/D27 -> 1.67258 | H27: 25 | I27: =I26+1 -> 29 | K27: =K26+J27 -> 32800 | L27: =Sheet2!AA25 -> 74665 | M27: =Sheet2!AB25 -> 199859 | N27: =L27/K27 -> 2.276372 | O27: 25 | P27: =P26+1 -> 29 | Q27: =Sheet2!AG25 -> 0 | R27: =R26+Q27 -> 50000 | S27: =Sheet2!AJ25 -> 83838 | T27: =Sheet2!AK25 -> 353045 | U27: =S27/R27 -> 1.67676
A28: 26 | B28: =B27+1 -> 30 | D28: =SUM($C$3:C28) -> 50000 | E28: =Sheet2!G26 -> 87985 | F28: =Sheet2!H26 -> 360862 | G28: =E28/D28 -> 1.7597 | H28: 26 | I28: =I27+1 -> 30 | K28: =K27+J28 -> 32800 | L28: =Sheet2!AA26 -> 78630 | M28: =Sheet2!AB26 -> 206686 | N28: =L28/K28 -> 2.3972561 | O28: 26 | P28: =P27+1 -> 30 | Q28: =Sheet2!AG26 -> 0 | R28: =R27+Q28 -> 50000 | S28: =Sheet2!AJ26 -> 88043 | T28: =Sheet2!AK26 -> 361097 | U28: =S28/R28 -> 1.76086
A29: 27 | B29: =B28+1 -> 31 | D29: =SUM($C$3:C29) -> 50000 | E29: =Sheet2!G27 -> 92578 | F29: =Sheet2!H27 -> 369766 | G29: =E29/D29 -> 1.85156 | H29: 27 | I29: =I28+1 -> 31 | K29: =K28+J29 -> 32800 | L29: =Sheet2!AA27 -> 82806 | M29: =Sheet2!AB27 -> 213736 | N29: =L29/K29 -> 2.5245732 | O29: 27 | P29: =P28+1 -> 31 | Q29: =Sheet2!AG27 -> 0 | R29: =R28+Q29 -> 50000 | S29: =Sheet2!AJ27 -> 92466 | T29: =Sheet2!AK27 -> 369319 | U29: =S29/R29 -> 1.84932
A30: 28 | B30: =B29+1 -> 32 | D30: =SUM($C$3:C30) -> 50000 | E30: =Sheet2!G28 -> 97406 | F30: =Sheet2!H28 -> 378879 | G30: =E30/D30 -> 1.94812 | H30: 28 | I30: =I29+1 -> 32 | K30: =K29+J30 -> 32800 | L30: =Sheet2!AA28 -> 87202 | M30: =Sheet2!AB28 -> 221027 | N30: =L30/K30 -> 2.6585976 | O30: 28 | P30: =P29+1 -> 32 | Q30: =Sheet2!AG28 -> 0 | R30: =R29+Q30 -> 50000 | S30: =Sheet2!AJ28 -> 97112 | T30: =Sheet2!AK28 -> 377735 | U30: =S30/R30 -> 1.94224
A31: 29 | B31: =B30+1 -> 33 | D31: =SUM($C$3:C31) -> 50000 | E31: =Sheet2!G29 -> 102485 | F31: =Sheet2!H29 -> 388244 | G31: =E31/D31 -> 2.0497 | H31: 29 | I31: =I30+1 -> 33 | K31: =K30+J31 -> 32800 | L31: =Sheet2!AA29 -> 91826 | M31: =Sheet2!AB29 -> 228571 | N31: =L31/K31 -> 2.7995732 | O31: 29 | P31: =P30+1 -> 33 | Q31: =Sheet2!AG29 -> 0 | R31: =R30+Q31 -> 50000 | S31: =Sheet2!AJ29 -> 101988 | T31: =Sheet2!AK29 -> 386363 | U31: =S31/R31 -> 2.03976
A32: 30 | B32: =B31+1 -> 34 | D32: =SUM($C$3:C32) -> 50000 | E32: =Sheet2!G30 -> 107816 | F32: =Sheet2!H30 -> 397846 | G32: =E32/D32 -> 2.15632 | H32: 30 | I32: =I31+1 -> 34 | K32: =K31+J32 -> 32800 | L32: =Sheet2!AA30 -> 96690 | M32: =Sheet2!AB30 -> 236371 | N32: =L32/K32 -> 2.9478659 | O32: 30 | P32: =P31+1 -> 34 | Q32: =Sheet2!AG30 -> 0 | R32: =R31+Q32 -> 50000 | S32: =Sheet2!AJ30 -> 107103 | T32: =Sheet2!AK30 -> 395214 | U32: =S32/R32 -> 2.14206
A33: 31 | B33: =B32+1 -> 35 | D33: =SUM($C$3:C33) -> 50000 | E33: =Sheet2!G31 -> 113420 | F33: =Sheet2!H31 -> 407707 | G33: =E33/D33 -> 2.2684 | H33: 31 | I33: =I32+1 -> 35 | K33: =K32+J33 -> 32800 | L33: =Sheet2!AA31 -> 101806 | M33: =Sheet2!AB31 -> 244438 | N33: =L33/K33 -> 3.1038415 | O33: 31 | P33: =P32+1 -> 35 | Q33: =Sheet2!AG31 -> 0 | R33: =R32+Q33 -> 50000 | S33: =Sheet2!AJ31 -> 112469 | T33: =Sheet2!AK31 -> 404288 | U33: =S33/R33 -> 2.24938
A34: 32 | B34: =B33+1 -> 36 | D34: =SUM($C$3:C34) -> 50000 | E34: =Sheet2!G32 -> 119309 | F34: =Sheet2!H32 -> 417835 | G34: =E34/D34 -> 2.38618 | H34: 32 | I34: =I33+1 -> 36 | K34: =K33+J34 -> 32800 | L34: =Sheet2!AA32 -> 107182 | M34: =Sheet2!AB32 -> 252783 | N34: =L34/K34 -> 3.2677439 | O34: 32 | P34: =P33+1 -> 36 | Q34: =Sheet2!AG32 -> 0 | R34: =R33+Q34 -> 50000 | S34: =Sheet2!AJ32 -> 118099 | T34: =Sheet2!AK32 -> 413598 | U34: =S34/R34 -> 2.36198
... A40: 38 | B40: =B39+1 -> 42 | D40: =SUM($C$3:C40) -> 50000 | E40: =Sheet2!G38 -> 161330 | F40: =Sheet2!H38 -> 484985 | G40: =E40/D40 -> 3.2266 | H40: 38 | I40: =I39+1 -> 42 | K40: =K39+J40 -> 32800 | L40: =Sheet2!AA38 -> 145769 | M40: =Sheet2!AB38 -> 309448 | N40: =L40/K40 -> 4.4441768 | O40: 38 | P40: =P39+1 -> 42 | Q40: =Sheet2!AG38 -> 0 | R40: =R39+Q40 -> 50000 | S40: =Sheet2!AJ38 -> 158061 | T40: =Sheet2!AK38 -> 475157 | U40: =S40/R40 -> 3.16122
A41: 39 | B41: =B40+1 -> 43 | D41: =SUM($C$3:C41) -> 50000 | E41: =Sheet2!G39 -> 169613 | F41: =Sheet2!H39 -> 497326 | G41: =E41/D41 -> 3.39226 | H41: 39 | I41: =I40+1 -> 43 | K41: =K40+J41 -> 32800 | L41: =Sheet2!AA39 -> 153406 | M41: =Sheet2!AB39 -> 320103 | N41: =L41/K41 -> 4.6770122 | O41: 39 | P41: 39 | Q41: =Sheet2!AG39 -> 0 | R41: =R40+Q41 -> 50000 | S41: =Sheet2!AJ39 -> 165906 | T41: =Sheet2!AK39 -> 486457 | U41: =S41/R41 -> 3.31812
A42: 40 | B42: =B41+1 -> 44 | D42: =SUM($C$3:C42) -> 50000 | E42: =Sheet2!G40 -> 178335 | F42: =Sheet2!H40 -> 509980 | G42: =E42/D42 -> 3.5667 | H42: 40 | I42: =I41+1 -> 44 | K42: =K41+J42 -> 32800 | L42: =Sheet2!AA40 -> 161449 | M42: =Sheet2!AB40 -> 331129 | N42: =L42/K42 -> 4.9222256 | O42: 40 | P42: 40 | Q42: =Sheet2!AG40 -> 0 | R42: =R41+Q42 -> 50000 | S42: =Sheet2!AJ40 -> 174162 | T42: =Sheet2!AK40 -> 498048 | U42: =S42/R42 -> 3.48324
A43: 41 | B43: =B42+1 -> 45 | D43: =SUM($C$3:C43) -> 50000 | E43: =Sheet2!G41 -> 187511 | F43: =Sheet2!H41 -> 522957 | G43: =E43/D43 -> 3.75022 | H43: 41 | I43: =I42+1 -> 45 | K43: =K42+J43 -> 32800 | L43: =Sheet2!AA41 -> 169913 | M43: =Sheet2!AB41 -> 342532 | N43: =L43/K43 -> 5.1802744 | O43: 41 | P43: 41 | Q43: =Sheet2!AG41 -> 0 | R43: =R42+Q43 -> 50000 | S43: =Sheet2!AJ41 -> 182836 | T43: =Sheet2!AK41 -> 509916 | U43: =S43/R43 -> 3.65672
A44: 42 | B44: =B43+1 -> 46 | D44: =SUM($C$3:C44) -> 50000 | E44: =Sheet2!G42 -> 197172 | F44: =Sheet2!H42 -> 536274 | G44: =E44/D44 -> 3.94344 | H44: 42 | I44: =I43+1 -> 46 | K44: =K43+J44 -> 32800 | L44: =Sheet2!AA42 -> 178830 | M44: =Sheet2!AB42 -> 354336 | N44: =L44/K44 -> 5.4521341 | O44: 42 | P44: 42 | Q44: =Sheet2!AG42 -> 0 | R44: =R43+Q44 -> 50000 | S44: =Sheet2!AJ42 -> 191958 | T44: =Sheet2!AK42 -> 522094 | U44: =S44/R44 -> 3.83916
A45: 43 | B45: =B44+1 -> 47 | D45: =SUM($C$3:C45) -> 50000 | E45: =Sheet2!G43 -> 207335 | F45: =Sheet2!H43 -> 549901 | G45: =E45/D45 -> 4.1467 | H45: 43 | I45: =I44+1 -> 47 | K45: =K44+J45 -> 32800 | L45: =Sheet2!AA43 -> 188218 | M45: =Sheet2!AB43 -> 366547 | N45: =L45/K45 -> 5.7383537 | O45: 43 | P45: 43 | Q45: =Sheet2!AG43 -> 0 | R45: =R44+Q45 -> 50000 | S45: =Sheet2!AJ43 -> 201550 | T45: =Sheet2!AK43 -> 534560 | U45: =S45/R45 -> 4.031
...

Sheet Table 2
A1: Ruhan 10 Pay | H1: Yaneesh - 10 Pay | O1: Ruhan L65
A2: Yr | B2: Age | C2: Annual Premium | D2: Cum Outlay | E2: Cash Value | F2: Death Benefit | G2: Outlay to Cash Value % | H2: Yr | I2: Age | J2: Annual Premium | K2: Cum Outlay | L2: Cash Value | M2: Death Benefit | N2: Outlay to Cash Value % | O2: Yr | P2: Age | Q2: Annual Premium | R2: Cum Outlay | S2: Cash Value | T2: Death Benefit | U2: Outlay to Cash Value %
A3: 1 | B3: 5 | C3: =Sheet4!D1 -> 5000 | D3: =C3 -> 5000 | E3: =Sheet4!G1 -> 1849 | F3: =Sheet4!H1 -> 156927 | G3: =E3/D3 -> 0.3698 | H3: 1 | I3: 44 | J3: ='Table 1'!#REF! -> #REF! | K3: =J3 -> #REF! | L3: ='Table 1'!#REF! -> #REF! | M3: ='Table 1'!#REF! -> #REF! | N3: =L3/K3 -> #REF! | O3: 1 | P3: 5 | Q3: 5000 | R3: 5000 | S3: 2628 | T3: 406976 | U3: 0.5256
A4: 2 | B4: =B3+1 -> 6 | C4: =Sheet4!D2 -> 5000 | D4: =D3+C4 -> 10000 | E4: =Sheet4!G2 -> 5100 | F4: =Sheet4!H2 -> 158052 | G4: =E4/D4 -> 0.51 | H4: 2 | I4: =I3+1 -> 45 | J4: ='Table 1'!#REF! -> #REF! | K4: =K3+J4 -> #REF! | L4: ='Table 1'!#REF! -> #REF! | M4: ='Table 1'!#REF! -> #REF! | N4: =L4/K4 -> #REF! | O4: 2 | P4: =P3+1 -> 6 | Q4: 5000 | R4: 10000 | S4: 5762 | T4: 428178 | U4: 0.5762
A5: 3 | B5: =B4+1 -> 7 | C5: =Sheet4!D3 -> 5000 | D5: =D4+C5 -> 15000 | E5: =Sheet4!G3 -> 10153 | F5: =Sheet4!H3 -> 159691 | G5: =E5/D5 -> 0.67686667 | H5: 3 | I5: =I4+1 -> 46 | J5: ='Table 1'!#REF! -> #REF! | K5: =K4+J5 -> #REF! | L5: ='Table 1'!#REF! -> #REF! | M5: ='Table 1'!#REF! -> #REF! | N5: =L5/K5 -> #REF! | O5: 3 | P5: =P4+1 -> 7 | Q5: 5000 | R5: 15000 | S5: 10520 | T5: 449399 | U5: 0.70133333
A6: 4 | B6: =B5+1 -> 8 | C6: =Sheet4!D4 -> 5000 | D6: =D5+C6 -> 20000 | E6: =Sheet4!G4 -> 15446 | F6: =Sheet4!H4 -> 161853 | G6: =E6/D6 -> 0.7723 | H6: 4 | I6: =I5+1 -> 47 | J6: ='Table 1'!#REF! -> #REF! | K6: =K5+J6 -> #REF! | L6: ='Table 1'!#REF! -> #REF! | M6: ='Table 1'!#REF! -> #REF! | N6: =L6/K6 -> #REF! | O6: 4 | P6: =P5+1 -> 8 | Q6: 5000 | R6: 20000 | S6: 15494 | T6: 470610 | U6: 0.7747
A7: 5 | B7: =B6+1 -> 9 | C7: =Sheet4!D5 -> 5000 | D7: =D6+C7 -> 25000 | E7: =Sheet4!G5 -> 20995 | F7: =Sheet4!H5 -> 164544 | G7: =E7/D7 -> 0.8398 | H7: 5 | I7: =I6+1 -> 48 | J7: ='Table 1'!#REF! -> #REF! | K7: =K6+J7 -> #REF! | L7: ='Table 1'!#REF! -> #REF! | M7: ='Table 1'!#REF! -> #REF! | N7: =L7/K7 -> #REF! | O7: 5 | P7: =P6+1 -> 9 | Q7: 5000 | R7: 25000 | S7: 20705 | T7: 491792 | U7: 0.8282
A8: 6 | B8: =B7+1 -> 10 | C8: =Sheet4!D6 -> 5000 | D8: =D7+C8 -> 30000 | E8: =Sheet4!G6 -> 26853 | F8: =Sheet4!H6 -> 167934 | G8: =E8/D8 -> 0.8951 | H8: 6 | I8: =I7+1 -> 49 | J8: ='Table 1'!#REF! -> #REF! | K8: =K7+J8 -> #REF! | L8: ='Table 1'!#REF! -> #REF! | M8: ='Table 1'!#REF! -> #REF! | N8: =L8/K8 -> #REF! | O8: 6 | P8: =P7+1 -> 10 | Q8: 5000 | R8: 30000 | S8: 26166 | T8: 513056 | U8: 0.8722
A9: 7 | B9: =B8+1 -> 11 | C9: =Sheet4!D7 -> 5000 | D9: =D8+C9 -> 35000 | E9: =Sheet4!G7 -> 33036 | F9: =Sheet4!H7 -> 172035 | G9: =E9/D9 -> 0.94388571 | H9: 7 | I9: =I8+1 -> 50 | J9: ='Table 1'!#REF! -> #REF! | K9: =K8+J9 -> #REF! | L9: ='Table 1'!#REF! -> #REF! | M9: ='Table 1'!#REF! -> #REF! | N9: =L9/K9 -> #REF! | O9: 7 | P9: =P8+1 -> 11 | Q9: 5000 | R9: 35000 | S9: 31893 | T9: 534415 | U9: 0.91122857
A10: 8 | B10: =B9+1 -> 12 | C10: =Sheet4!D8 -> 5000 | D10: =D9+C10 -> 40000 | E10: =Sheet4!G8 -> 39566 | F10: =Sheet4!H8 -> 176873 | G10: =E10/D10 -> 0.98915 | H10: =H9+1 -> 8 | I10: =I9+1 -> 51 | J10: ='Table 1'!#REF! -> #REF! | K10: =K9+J10 -> #REF! | L10: ='Table 1'!#REF! -> #REF! | M10: ='Table 1'!#REF! -> #REF! | N10: =L10/K10 -> #REF! | O10: 8 | P10: =P9+1 -> 12 | Q10: 5000 | R10: 40000 | S10: 37907 | T10: 555934 | U10: 0.947675
A11: 9 | B11: =B10+1 -> 13 | C11: =Sheet4!D9 -> 5000 | D11: =D10+C11 -> 45000 | E11: =Sheet4!G9 -> 46453 | F11: =Sheet4!H9 -> 182444 | G11: =E11/D11 -> 1.0322889 | H11: 9 | I11: =I10+1 -> 52 | J11: ='Table 1'!#REF! -> #REF! | K11: =K10+J11 -> #REF! | L11: ='Table 1'!#REF! -> #REF! | M11: ='Table 1'!#REF! -> #REF! | N11: =L11/K11 -> #REF! | O11: 9 | P11: =P10+1 -> 13 | Q11: 5000 | R11: 45000 | S11: 44195 | T11: 577561 | U11: 0.98211111
A12: 10 | B12: =B11+1 -> 14 | C12: =Sheet4!D10 -> 5000 | D12: =D11+C12 -> 50000 | E12: =Sheet4!G10 -> 53721 | F12: =Sheet4!H10 -> 188771 | G12: =E12/D12 -> 1.07442 | H12: 10 | I12: =I11+1 -> 53 | J12: ='Table 1'!#REF! -> #REF! | K12: =K11+J12 -> #REF! | L12: ='Table 1'!#REF! -> #REF! | M12: ='Table 1'!#REF! -> #REF! | N12: =L12/K12 -> #REF! | O12: 10 | P12: =P11+1 -> 14 | Q12: 5000 | R12: 50000 | S12: 50785 | T12: 599380 | U12: 1.0157
A13: 11 | B13: =B12+1 -> 15 | C13: =Sheet4!D11 -> 0 | D13: =D12+C13 -> 50000 | E13: =Sheet4!G11 -> 56612 | F13: =Sheet4!H11 -> 195146 | G13: =E13/D13 -> 1.13224 | H13: 11 | I13: =I12+1 -> 54 | K13: =K12+J13 -> #REF! | L13: ='Table 1'!#REF! -> #REF! | M13: ='Table 1'!#REF! -> #REF! | N13: =L13/K13 -> #REF! | O13: 11 | P13: =P12+1 -> 15 | Q13: 0 | R13: 50000 | S13: 53162 | T13: 322665 | U13: 1.06324
A14: 12 | B14: =B13+1 -> 16 | C14: =Sheet4!D12 -> 0 | D14: =D13+C14 -> 50000 | E14: =Sheet4!G12 -> 59652 | F14: =Sheet4!H12 -> 201759 | G14: =E14/D14 -> 1.19304 | H14: 12 | I14: =I13+1 -> 55 | K14: =K13+J14 -> #REF! | L14: ='Table 1'!#REF! -> #REF! | M14: ='Table 1'!#REF! -> #REF! | N14: =L14/K14 -> #REF! | O14: 12 | P14: =P13+1 -> 16 | Q14: 0 | R14: 50000 | S14: 55641 | T14: 328458 | U14: 1.11282
A15: 13 | B15: =B14+1 -> 17 | C15: =Sheet4!D13 -> 0 | D15: =D14+C15 -> 50000 | E15: =Sheet4!G13 -> 62840 | F15: =Sheet4!H13 -> 208624 | G15: =E15/D15 -> 1.2568 | H15: 13 | I15: =I14+1 -> 56 | K15: =K14+J15 -> #REF! | L15: ='Table 1'!#REF! -> #REF! | M15: ='Table 1'!#REF! -> #REF! | N15: =L15/K15 -> #REF! | O15: 13 | P15: =P14+1 -> 17 | Q15: 0 | R15: 50000 | S15: 58227 | T15: 334504 | U15: 1.16454
A16: 14 | B16: =B15+1 -> 18 | C16: =Sheet4!D14 -> 0 | D16: =D15+C16 -> 50000 | E16: =Sheet4!G14 -> 66184 | F16: =Sheet4!H14 -> 215760 | G16: =E16/D16 -> 1.32368 | H16: 14 | I16: =I15+1 -> 57 | K16: =K15+J16 -> #REF! | L16: ='Table 1'!#REF! -> #REF! | M16: ='Table 1'!#REF! -> #REF! | N16: =L16/K16 -> #REF! | O16: 14 | P16: =P15+1 -> 18 | Q16: 0 | R16: 50000 | S16: 60905 | T16: 340806 | U16: 1.2181
A17: 15 | B17: =B16+1 -> 19 | C17: =Sheet4!D15 -> 0 | D17: =D16+C17 -> 50000 | E17: =Sheet4!G15 -> 69685 | F17: =Sheet4!H15 -> 223127 | G17: =E17/D17 -> 1.3937 | H17: 15 | I17: =I16+1 -> 58 | K17: =K16+J17 -> #REF! | L17: ='Table 1'!#REF! -> #REF! | M17: ='Table 1'!#REF! -> #REF! | N17: =L17/K17 -> #REF! | O17: 15 | P17: =P16+1 -> 19 | Q17: 0 | R17: 50000 | S17: 63696 | T17: 347342 | U17: 1.27392
A18: 16 | B18: =B17+1 -> 20 | C18: =Sheet4!D16 -> 0 | D18: =D17+C18 -> 50000 | E18: =Sheet4!G16 -> 73374 | F18: =Sheet4!H16 -> 230763 | G18: =E18/D18 -> 1.46748 | H18: 16 | I18: =I17+1 -> 59 | K18: =K17+J18 -> #REF! | L18: ='Table 1'!#REF! -> #REF! | M18: ='Table 1'!#REF! -> #REF! | N18: =L18/K18 -> #REF! | O18: 16 | P18: =P17+1 -> 20 | Q18: 0 | R18: 50000 | S18: 66711 | T18: 354528 | U18: 1.33422
A19: 17 | B19: =B18+1 -> 21 | C19: =Sheet4!D17 -> 0 | D19: =D18+C19 -> 50000 | E19: =Sheet4!G17 -> 77259 | F19: =Sheet4!H17 -> 238674 | G19: =E19/D19 -> 1.54518 | H19: 17 | I19: =I18+1 -> 60 | K19: =K18+J19 -> #REF! | L19: ='Table 1'!#REF! -> #REF! | M19: ='Table 1'!#REF! -> #REF! | N19: =L19/K19 -> #REF! | O19: 17 | P19: =P18+1 -> 21 | Q19: 0 | R19: 50000 | S19: 69909 | T19: 362073 | U19: 1.39818
A20: 18 | B20: =B19+1 -> 22 | C20: =Sheet4!D18 -> 0 | D20: =D19+C20 -> 50000 | E20: =Sheet4!G18 -> 81351 | F20: =Sheet4!H18 -> 246861 | G20: =E20/D20 -> 1.62702 | H20: 18 | I20: =I19+1 -> 61 | K20: =K19+J20 -> #REF! | L20: ='Table 1'!#REF! -> #REF! | M20: ='Table 1'!#REF! -> #REF! | N20: =L20/K20 -> #REF! | O20: 18 | P20: =P19+1 -> 22 | Q20: 0 | R20: 50000 | S20: 73299 | T20: 369990 | U20: 1.46598
A21: 19 | B21: =B20+1 -> 23 | C21: =Sheet4!D19 -> 0 | D21: =D20+C21 -> 50000 | E21: =Sheet4!G19 -> 85667 | F21: =Sheet4!H19 -> 255349 | G21: =E21/D21 -> 1.71334 | H21: 19 | I21: =I20+1 -> 62 | K21: =K20+J21 -> #REF! | L21: ='Table 1'!#REF! -> #REF! | M21: ='Table 1'!#REF! -> #REF! | N21: =L21/K21 -> #REF! | O21: 19 | P21: =P20+1 -> 23 | Q21: 0 | R21: 50000 | S21: 76893 | T21: 378278 | U21: 1.53786
A22: 20 | B22: =B21+1 -> 24 | C22: =Sheet4!D20 -> 0 | D22: =D21+C22 -> 50000 | E22: =Sheet4!G20 -> 90211 | F22: =Sheet4!H20 -> 264130 | G22: =E22/D22 -> 1.80422 | H22: 20 | I22: =I21+1 -> 63 | K22: =K21+J22 -> #REF! | L22: ='Table 1'!#REF! -> #REF! | M22: ='Table 1'!#REF! -> #REF! | N22: =L22/K22 -> #REF! | O22: 20 | P22: =P21+1 -> 24 | Q22: 0 | R22: 50000 | S22: 80704 | T22: 386941 | U22: 1.61408
A23: 21 | B23: =B22+1 -> 25 | C23: =Sheet4!D21 -> 0 | D23: =D22+C23 -> 50000 | E23: =Sheet4!G21 -> 94993 | F23: =Sheet4!H21 -> 273212 | G23: =E23/D23 -> 1.89986 | H23: 21 | I23: =I22+1 -> 64 | K23: =K22+J23 -> #REF! | L23: ='Table 1'!#REF! -> #REF! | M23: ='Table 1'!#REF! -> #REF! | N23: =L23/K23 -> #REF! | O23: 21 | P23: =P22+1 -> 25 | Q23: 0 | R23: 50000 | S23: 84722 | T23: 395878 | U23: 1.69444
A24: 22 | B24: =B23+1 -> 26 | C24: =Sheet4!D22 -> 0 | D24: =D23+C24 -> 50000 | E24: =Sheet4!G22 -> 100034 | F24: =Sheet4!H22 -> 282614 | G24: =E24/D24 -> 2.00068 | H24: 22 | I24: =I23+1 -> 65 | K24: =K23+J24 -> #REF! | L24: ='Table 1'!#REF! -> #REF! | M24: ='Table 1'!#REF! -> #REF! | N24: =L24/K24 -> #REF! | O24: 22 | P24: =P23+1 -> 26 | Q24: 0 | R24: 50000 | S24: 88943 | T24: 405022 | U24: 1.77886
... A40: 38 | B40: =B39+1 -> 42 | C40: =Sheet4!D38 -> 0 | D40: =D39+C40 -> 50000 | E40: =Sheet4!G38 -> 228177 | F40: =Sheet4!H38 -> 484390 | G40: =E40/D40 -> 4.56354 | H40: 38 | I40: =I39+1 -> 81 | K40: =K39+J40 -> #REF! | L40: ='Table 1'!#REF! -> #REF! | M40: ='Table 1'!#REF! -> #REF! | N40: =L40/K40 -> #REF! | O40: 38 | P40: =P39+1 -> 42 | Q40: 0 | R40: 50000 | S40: 194485 | T40: 584653 | U40: 3.8897
A41: 39 | B41: =B40+1 -> 43 | C41: =Sheet4!D39 -> 0 | D41: =D40+C41 -> 50000 | E41: =Sheet4!G39 -> 240137 | F41: =Sheet4!H39 -> 501080 | G41: =E41/D41 -> 4.80274 | H41: 39 | I41: =I40+1 -> 82 | K41: =K40+J41 -> #REF! | L41: ='Table 1'!#REF! -> #REF! | M41: ='Table 1'!#REF! -> #REF! | N41: =L41/K41 -> #REF! | O41: 39 | P41: 39 | Q41: 0 | R41: 50000 | S41: 204160 | T41: 598623 | U41: 4.0832
A42: 40 | B42: =B41+1 -> 44 | C42: =Sheet4!D40 -> 0 | D42: =D41+C42 -> 50000 | E42: =Sheet4!G40 -> 252733 | F42: =Sheet4!H40 -> 518351 | G42: =E42/D42 -> 5.05466 | H42: 40 | I42: =I41+1 -> 83 | K42: =K41+J42 -> #REF! | L42: ='Table 1'!#REF! -> #REF! | M42: ='Table 1'!#REF! -> #REF! | N42: =L42/K42 -> #REF! | O42: 40 | P42: 40 | Q42: 0 | R42: 50000 | S42: 214344 | T42: 612954 | U42: 4.28688
A43: 41 | B43: =B42+1 -> 45 | C43: =Sheet4!D41 -> 0 | D43: =D42+C43 -> 50000 | E43: =Sheet4!G41 -> 265988 | F43: =Sheet4!H41 -> 536213 | G43: =E43/D43 -> 5.31976 | H43: 41 | I43: =I42+1 -> 84 | K43: =K42+J43 -> #REF! | L43: ='Table 1'!#REF! -> #REF! | M43: ='Table 1'!#REF! -> #REF! | N43: =L43/K43 -> #REF! | O43: 41 | P43: 41 | Q43: 0 | R43: 50000 | S43: 225042 | T43: 627627 | U43: 4.50084
A44: 42 | B44: =B43+1 -> 46 | C44: =Sheet4!D42 -> 0 | D44: =D43+C44 -> 50000 | E44: =Sheet4!G42 -> 279953 | F44: =Sheet4!H42 -> 554702 | G44: =E44/D44 -> 5.59906 | H44: 42 | I44: =I43+1 -> 85 | K44: =K43+J44 -> #REF! | L44: ='Table 1'!#REF! -> #REF! | M44: ='Table 1'!#REF! -> #REF! | N44: =L44/K44 -> #REF! | O44: 42 | P44: 42 | Q44: 0 | R44: 50000 | S44: 236296 | T44: 642685 | U44: 4.72592
A45: 43 | B45: =B44+1 -> 47 | C45: =Sheet4!D43 -> 0 | D45: =D44+C45 -> 50000 | E45: =Sheet4!G43 -> 294655 | F45: =Sheet4!H43 -> 573828 | G45: =E45/D45 -> 5.8931 | H45: 43 | I45: =I44+1 -> 86 | K45: =K44+J45 -> #REF! | L45: ='Table 1'!#REF! -> #REF! | M45: ='Table 1'!#REF! -> #REF! | N45: =L45/K45 -> #REF! | O45: 43 | P45: 43 | Q45: 0 | R45: 50000 | S45: 248130 | T45: 658100 | U45: 4.9626
A46: 44 | B46: =B45+1 -> 48 | C46: =Sheet4!D44 -> 0 | D46: =D45+C46 -> 50000 | E46: =Sheet4!G44 -> 310133 | F46: =Sheet4!H44 -> 593602 | G46: =E46/D46 -> 6.20266 | H46: 44 | I46: =I45+1 -> 87 | K46: =K45+J46 -> #REF! | L46: ='Table 1'!#REF! -> #REF! | M46: ='Table 1'!#REF! -> #REF! | N46: =L46/K46 -> #REF! | O46: 44 | P46: 44 | Q46: 0 | R46: 50000 | S46: 260572 | T46: 673888 | U46: 5.21144
A47: 45 | B47: =B46+1 -> 49 | C47: =Sheet4!D45 -> 0 | D47: =D46+C47 -> 50000 | E47: =Sheet4!G45 -> 326430 | F47: =Sheet4!H45 -> 614051 | G47: =E47/D47 -> 6.5286 | H47: 45 | I47: =I46+1 -> 88 | K47: =K46+J47 -> #REF! | L47: ='Table 1'!#REF! -> #REF! | M47: ='Table 1'!#REF! -> #REF! | N47: =L47/K47 -> #REF! | O47: 45 | P47: 45 | Q47: 0 | R47: 50000 | S47: 273662 | T47: 690073 | U47: 5.47324
A48: 46 | B48: =B47+1 -> 50 | C48: =Sheet4!D46 -> 0 | D48: =D47+C48 -> 50000 | E48: =Sheet4!G46 -> 343575 | F48: =Sheet4!H46 -> 635180 | G48: =E48/D48 -> 6.8715 | H48: 46 | I48: =I47+1 -> 89 | K48: =K47+J48 -> #REF! | L48: ='Table 1'!#REF! -> #REF! | M48: ='Table 1'!#REF! -> #REF! | N48: =L48/K48 -> #REF! | O48: 46 | P48: 46 | Q48: 0 | R48: 50000 | S48: 287425 | T48: 706619 | U48: 5.7485
A49: 47 | B49: =B48+1 -> 51 | C49: =Sheet4!D47 -> 0 | D49: =D48+C49 -> 50000 | E49: =Sheet4!G47 -> 361628 | F49: =Sheet4!H47 -> 657051 | G49: =E49/D49 -> 7.23256 | H49: 47 | I49: =I48+1 -> 90 | K49: =K48+J49 -> #REF! | L49: ='Table 1'!#REF! -> #REF! | M49: ='Table 1'!#REF! -> #REF! | N49: =L49/K49 -> #REF! | O49: 47 | P49: 47 | Q49: 0 | R49: 50000 | S49: 301886 | T49: 723584 | U49: 6.03772
A50: 48 | B50: =B49+1 -> 52 | C50: =Sheet4!D48 -> 0 | D50: =D49+C50 -> 50000 | E50: =Sheet4!G48 -> 380615 | F50: =Sheet4!H48 -> 679670 | G50: =E50/D50 -> 7.6123 | H50: 48 | I50: =I49+1 -> 91 | K50: =K49+J50 -> #REF! | L50: ='Table 1'!#REF! -> #REF! | M50: ='Table 1'!#REF! -> #REF! | N50: =L50/K50 -> #REF! | O50: 48 | P50: 48 | Q50: 0 | R50: 50000 | S50: 317078 | T50: 740975 | U50: 6.34156
A51: 49 | B51: =B50+1 -> 53 | C51: =Sheet4!D49 -> 0 | D51: =D50+C51 -> 50000 | E51: =Sheet4!G49 -> 400574 | F51: =Sheet4!H49 -> 703070 | G51: =E51/D51 -> 8.01148 | H51: 49 | I51: =I50+1 -> 92 | K51: =K50+J51 -> #REF! | L51: ='Table 1'!#REF! -> #REF! | M51: ='Table 1'!#REF! -> #REF! | N51: =L51/K51 -> #REF! | O51: 49 | P51: 49 | Q51: 0 | R51: 50000 | S51: 333012 | T51: 758794 | U51: 6.66024
A52: 50 | B52: =B51+1 -> 54 | C52: =Sheet4!D50 -> 0 | D52: =D51+C52 -> 50000 | E52: =Sheet4!G50 -> 421557 | F52: =Sheet4!H50 -> 727274 | G52: =E52/D52 -> 8.43114 | H52: 50 | I52: =I51+1 -> 93 | K52: =K51+J52 -> #REF! | L52: ='Table 1'!#REF! -> #REF! | M52: ='Table 1'!#REF! -> #REF! | N52: =L52/K52 -> #REF! | O52: 50 | P52: 50 | Q52: 0 | R52: 50000 | S52: 349716 | T52: 777060 | U52: 6.99432
... A55: 53 | B55: =B54+1 -> 57 | C55: =Sheet4!D53 -> 0 | D55: =D54+C55 -> 50000 | E55: =Sheet4!G53 -> 491189 | F55: =Sheet4!H53 -> 805189 | G55: =E55/D55 -> 9.82378 | H55: 53 | I55: =I54+1 -> 96 | K55: =K54+J55 -> #REF! | L55: ='Table 1'!#REF! -> #REF! | M55: ='Table 1'!#REF! -> #REF! | N55: =L55/K55 -> #REF! | O55: 53 | P55: 53 | Q55: 0 | R55: 50000 | S55: 404923 | T55: 834894 | U55: 8.09846

Sheet Sheet4
A1: 1 | B1: 5 | C1: 5000 | D1: 5000 | E1: 150 | F1: 150 | G1: 1849 | H1: 156927
A2: 2 | B2: 6 | C2: 5000 | D2: 5000 | E2: 274 | F2: 427 | G2: 5100 | H2: 158052
A3: 3 | B3: 7 | C3: 5000 | D3: 5000 | E3: 407 | F3: 842 | G3: 10153 | H3: 159691
A4: 4 | B4: 8 | C4: 5000 | D4: 5000 | E4: 547 | F4: 1406 | G4: 15446 | H4: 161853
A5: 5 | B5: 9 | C5: 5000 | D5: 5000 | E5: 695 | F5: 2128 | G5: 20995 | H5: 164544
A6: 6 | B6: 10 | C6: 5000 | D6: 5000 | E6: 892 | F6: 3063 | G6: 26853 | H6: 167934
A7: 7 | B7: 11 | C7: 5000 | D7: 5000 | E7: 1101 | F7: 4224 | G7: 33036 | H7: 172035
A8: 8 | B8: 12 | C8: 5000 | D8: 5000 | E8: 1325 | F8: 5632 | G8: 39566 | H8: 176873
A9: 9 | B9: 13 | C9: 5000 | D9: 5000 | E9: 1555 | F9: 7297 | G9: 46453 | H9: 182444
A10: 10 | B10: 14 | C10: 5000 | D10: 5000 | E10: 1801 | F10: 9241 | G10: 53721 | H10: 188771
A11: 11 | B11: 15 | C11: 0 | D11: 0 | E11: 1849 | F11: 11269 | G11: 56612 | H11: 195146
A12: 12 | B12: 16 | C12: 0 | D12: 0 | E12: 1955 | F12: 13441 | G12: 59652 | H12: 201759
... A117: 117 | B117: 121 | C117: 0 | D117: 0 | E117: 564883 | F117: 10922835 | G117: 11079134 | H117: 11079134
A118: Yr

Sheet Sheet3
A1: 5 | C1: 5000 | D1: 5000 | E1: 313 | F1: 2628 | G1: 2628 | H1: 406976
A2: 2 | B2: 6 | C2: 5000 | D2: 5000 | E2: 378 | F2: 5399 | G2: 5762 | H2: 428178
A3: 3 | B3: 7 | C3: 5000 | D3: 5000 | E3: 459 | F3: 8333 | G3: 10520 | H3: 449399
A4: 4 | B4: 8 | C4: 5000 | D4: 5000 | E4: 540 | F4: 11432 | G4: 15494 | H4: 470610
A5: 5 | B5: 9 | C5: 5000 | D5: 5000 | E5: 619 | F5: 14704 | G5: 20705 | H5: 491792
A6: 6 | B6: 10 | C6: 5000 | D6: 5000 | E6: 717 | F6: 18171 | G6: 26166 | H6: 513056
A7: 7 | B7: 11 | C7: 5000 | D7: 5000 | E7: 821 | F7: 21842 | G7: 31893 | H7: 534415
A8: 8 | B8: 12 | C8: 5000 | D8: 5000 | E8: 937 | F8: 25738 | G8: 37907 | H8: 555934
A9: 9 | B9: 13 | C9: 5000 | D9: 5000 | E9: 1049 | F9: 29860 | G9: 44195 | H9: 577561
A10: 10 | B10: 14 | C10: 5000 | D10: 5000 | E10: 1179 | F10: 34223 | G10: 50785 | H10: 599380
A11: 11 | B11: 15 | C11: 0 | D11: 0 | E11: 916 | F11: 916 | G11: 53162 | H11: 322665
A12: 12 | B12: 16 | C12: 0 | D12: 0 | E12: 981 | F12: 1923 | G12: 55641 | H12: 328458
A13: 13 | B13: 17 | C13: 0 | D13: 0 | E13: 1052 | F13: 3028 | G13: 58227 | H13: 334504
... A69: 69 | B69: 73 | C69: 0 | D69: 0 | E69: 23133 | F69: 652422 | G69: 872373 | H69: 1257711

Sheet Sheet2
B1: 5 | C1: 2500 | D1: 2500 | E1: 277 | F1: 277 | G1: 294 | H1: 220095 | L1: 44 | M1: 6878 | N1: 6878 | O1: 167 | P1: 167 | Q1: 2413 | R1: 100343 | V1: 5 | W1: 3280 | X1: 3280 | Y1: 96 | Z1: 96 | AA1: 1183 | AB1: 100402 | AD1: 5 | AF1: 2500 | AG1: 2500 | AH1: 152 | AI1: 1310 | AJ1: 1310 | AK1: 180186
A2: 2 | B2: 6 | C2: 2500 | D2: 2500 | E2: 294 | F2: 579 | G2: 759 | H2: 222407 | K2: 2 | L2: 45 | M2: 6878 | N2: 6878 | O2: 427 | P2: 597 | Q2: 6774 | R2: 101203 | U2: 2 | V2: 6 | W2: 3280 | X2: 3280 | Y2: 175 | Z2: 273 | AA2: 3263 | AB2: 101122 | AD2: 2 | AE2: 6 | AF2: 2500 | AG2: 2500 | AH2: 187 | AI2: 2693 | AJ2: 2852 | AK2: 190771
A3: 3 | B3: 7 | C3: 2500 | D3: 2500 | E3: 320 | F3: 916 | G3: 3083 | H3: 224855 | K3: 3 | L3: 46 | M3: 6878 | N3: 6878 | O3: 707 | P3: 1315 | Q3: 13373 | R3: 102605 | U3: 3 | V3: 7 | W3: 3280 | X3: 3280 | Y3: 260 | Z3: 539 | AA3: 6496 | AB3: 102170 | AD3: 3 | AE3: 7 | AF3: 2500 | AG3: 2500 | AH3: 228 | AI3: 4158 | AJ3: 5119 | AK3: 201366
A4: 4 | B4: 8 | C4: 2500 | D4: 2500 | E4: 341 | F4: 1283 | G4: 5499 | H4: 227386 | K4: 4 | L4: 47 | M4: 6878 | N4: 6878 | O4: 1003 | P4: 2340 | Q4: 20407 | R4: 104558 | U4: 4 | V4: 8 | W4: 3280 | X4: 3280 | Y4: 350 | Z4: 900 | AA4: 9883 | AB4: 103554 | AD4: 4 | AE4: 8 | AF4: 2500 | AG4: 2500 | AH4: 268 | AI4: 5705 | AJ4: 7491 | AK4: 211958
A5: 5 | B5: 9 | C5: 2500 | D5: 2500 | E5: 364 | F5: 1685 | G5: 8012 | H5: 230015 | K5: 5 | L5: 48 | M5: 6878 | N5: 6878 | O5: 1316 | P5: 3697 | Q5: 27903 | R5: 107077 | U5: 5 | V5: 9 | W5: 3280 | X5: 3280 | Y5: 444 | Z5: 1362 | AA5: 13433 | AB5: 105275 | AD5: 5 | AE5: 9 | AF5: 2500 | AG5: 2500 | AH5: 308 | AI5: 7340 | AJ5: 9978 | AK5: 222540
A6: 6 | B6: 10 | C6: 2500 | D6: 2500 | E6: 393 | F6: 2128 | G6: 10628 | H6: 232768 | K6: 6 | L6: 49 | M6: 6878 | N6: 6878 | O6: 1510 | P6: 5272 | Q6: 35751 | R6: 109918 | U6: 6 | V6: 10 | W6: 3280 | X6: 3280 | Y6: 571 | Z6: 1960 | AA6: 17181 | AB6: 107444 | AD6: 6 | AE6: 10 | AF6: 2500 | AG6: 2500 | AH6: 357 | AI6: 9071 | AJ6: 12586 | AK6: 233160
A7: 7 | B7: 11 | C7: 2500 | D7: 2500 | E7: 468 | F7: 2658 | G7: 13398 | H7: 235954 | K7: 7 | L7: 50 | M7: 6878 | N7: 6878 | O7: 1716 | P7: 7081 | Q7: 43972 | R7: 113091 | U7: 7 | V7: 11 | W7: 3280 | X7: 3280 | Y7: 704 | Z7: 2702 | AA7: 21136 | AB7: 110068 | AD7: 7 | AE7: 11 | AF7: 2500 | AG7: 2500 | AH7: 408 | AI7: 10904 | AJ7: 15323 | AK7: 243824
A8: 8 | B8: 12 | C8: 2500 | D8: 2500 | E8: 548 | F8: 3284 | G8: 16327 | H8: 239576 | K8: 8 | L8: 51 | M8: 6878 | N8: 6878 | O8: 1933 | P8: 9138 | Q8: 52581 | R8: 116602 | U8: 8 | V8: 12 | W8: 3280 | X8: 3280 | Y8: 847 | Z8: 3603 | AA8: 25314 | AB8: 113163 | AD8: 8 | AE8: 12 | AF8: 2500 | AG8: 2500 | AH8: 467 | AI8: 12850 | AJ8: 18200 | AK8: 254575
A9: 9 | B9: 13 | C9: 2500 | D9: 2500 | E9: 629 | F9: 4010 | G9: 19423 | H9: 243621 | K9: 9 | L9: 52 | M9: 6878 | N9: 6878 | O9: 2167 | P9: 11465 | Q9: 61601 | R9: 120473 | U9: 9 | V9: 13 | W9: 3280 | X9: 3280 | Y9: 995 | Z9: 4669 | AA9: 29721 | AB9: 116727 | AD9: 9 | AE9: 13 | AF9: 2500 | AG9: 2500 | AH9: 521 | AI9: 14907 | AJ9: 21210 | AK9: 265365
A10: 10 | B10: 14 | C10: 2500 | D10: 2500 | E10: 718 | F10: 4844 | G10: 22691 | H10: 248101 | K10: 10 | L10: 53 | M10: 6878 | N10: 6878 | O10: 2416 | P10: 14080 | Q10: 71055 | R10: 124713 | U10: 10 | V10: 14 | W10: 3280 | X10: 3280 | Y10: 1152 | Z10: 5912 | AA10: 34370 | AB10: 120776 | AD10: 10 | AE10: 14 | AF10: 2500 | AG10: 2500 | AH10: 586 | AI10: 17085 | AJ10: 24366 | AK10: 276256
A11: 11 | B11: 15 | C11: 2500 | D11: 2500 | E11: 759 | F11: 5742 | G11: 26079 | H11: 252706 | K11: 11 | L11: 54 | M11: 0 | N11: 0 | O11: 2591 | P11: 16915 | Q11: 74879 | R11: 129183 | U11: 11 | V11: 15 | W11: 0 | X11: 0 | Y11: 1179 | Z11: 7207 | AA11: 36217 | AB11: 124842 | AD11: 11 | AE11: 15 | AF11: 2500 | AG11: 2500 | AH11: 673 | AI11: 19407 | AJ11: 27683 | AK11: 287368
A12: 12 | B12: 16 | C12: 2500 | D12: 2500 | E12: 807 | F12: 6711 | G12: 29592 | H12: 257469 | K12: 12 | L12: 55 | M12: 0 | N12: 0 | O12: 2731 | P12: 19939 | Q12: 78905 | R12: 133814 | U12: 12 | V12: 16 | W12: 0 | X12: 0 | Y12: 1247 | Z12: 8592 | AA12: 38158 | AB12: 129060 | AD12: 12 | AE12: 16 | AF12: 2500 | AG12: 2500 | AH12: 767 | AI12: 21877 | AJ12: 31156 | AK12: 298721
A13: 13 | B13: 17 | C13: 2500 | D13: 2500 | E13: 859 | F13: 7755 | G13: 33228 | H13: 262403 | K13: 13 | L13: 56 | M13: 0 | N13: 0 | O13: 2878 | P13: 23159 | Q13: 83138 | R13: 138612 | U13: 13 | V13: 17 | W13: 0 | X13: 0 | Y13: 1319 | Z13: 10072 | AA13: 40193 | AB13: 133440 | AD13: 13 | AE13: 17 | AF13: 2500 | AG13: 2500 | AH13: 868 | AI13: 24504 | AJ13: 34794 | AK13: 310350
... A78: 78 | B78: 82 | C78: 0 | D78: 0 | E78: 31587 | F78: 951026 | G78: 1127384 | H78: 1392657 | K78: 78 | L78: 121 | M78: 0 | N78: 0 | O78: 103962 | P78: 1936818 | Q78: 2036818 | R78: 2036818 | U78: 78 | V78: 82 | W78: 0 | X78: 0 | Y78: 38374 | Z78: 991440 | AA78: 1078064 | AB78: 1244532 | AD78: 78 | AE78: 82 | AF78: 0 | AG78: 0 | AH78: 28882 | AI78: 801840 | AJ78: 1057063 | AK78: 1305790
A79: 79 | B79: 83 | C79: 0 | D79: 0 | E79: 32901 | F79: 998072 | G79: 1177053 | H79: 1432704 | K79: Yr | U79: 79 | V79: 83 | W79: 0 | X79: 0 | Y79: 40161 | Z79: 1041650 | AA79: 1129152 | AB79: 1290430 | AD79: 79 | AE79: 83 | AF79: 0 | AG79: 0 | AH79: 30076 | AI79: 843842 | AJ79: 1102861 | AK79: 1342399
A80: 80 | B80: 84 | C80: 0 | D80: 0 | E80: 34422 | F80: 1046671 | G80: 1228194 | H80: 1474016 | U80: 80 | V80: 84 | W80: 0 | X80: 0 | Y80: 42104 | Z80: 1093836 | AA80: 1182185 | AB80: 1338086 | AD80: 80 | AE80: 84 | AF80: 0 | AG80: 0 | AH80: 31454 | AI80: 887282 | AJ80: 1149981 | AK80: 1380148
A81: 81 | B81: 85 | C81: 0 | D81: 0 | E81: 35974 | F81: 1096790 | G81: 1280766 | H81: 1516614 | U81: 81 | V81: 85 | W81: 0 | X81: 0 | Y81: 44112 | Z81: 1148014 | AA81: 1237176 | AB81: 1387559 | AD81: 81 | AE81: 85 | AF81: 0 | AG81: 0 | AH81: 32863 | AI81: 932135 | AJ81: 1198384 | AK81: 1419062
A82: 82 | B82: 86 | C82: 0 | D82: 0 | E82: 37561 | F82: 1148326 | G82: 1334645 | H82: 1560532 | U82: 82 | V82: 86 | W82: 0 | X82: 0 | Y82: 46169 | Z82: 1204149 | AA82: 1294085 | AB82: 1438895 | AD82: 82 | AE82: 86 | AF82: 0 | AG82: 0 | AH82: 34300 | AI82: 978312 | AJ82: 1247953 | AK82: 1459167
A83: 83 | B83: 87 | C83: 0 | D83: 0 | E83: 39141 | F83: 1201148 | G83: 1389688 | H83: 1605759 | U83: 83 | V83: 87 | W83: 0 | X83: 0 | Y83: 48305 | Z83: 1262214 | AA83: 1352879 | AB83: 1492173 | AD83: 83 | AE83: 87 | AF83: 0 | AG83: 0 | AH83: 35727 | AI83: 1025695 | AJ83: 1298549 | AK83: 1500450
A84: 84 | B84: 88 | C84: 0 | D84: 0 | E84: 40660 | F84: 1255077 | G84: 1445699 | H84: 1652227 | U84: 84 | V84: 88 | W84: 0 | X84: 0 | Y84: 50419 | Z84: 1322128 | AA84: 1413475 | AB84: 1547369 | AD84: 84 | AE84: 88 | AF84: 0 | AG84: 0 | AH84: 37095 | AI84: 1074120 | AJ84: 1349988 | AK84: 1542843
A85: 85 | B85: 89 | C85: 0 | D85: 0 | E85: 42140 | F85: 1309940 | G85: 1502494 | H85: 1699904 | U85: 85 | V85: 89 | W85: 0 | X85: 0 | Y85: 52545 | Z85: 1383820 | AA85: 1475799 | AB85: 1604496 | AD85: 85 | AE85: 89 | AF85: 0 | AG85: 0 | AH85: 38419 | AI85: 1123428 | AJ85: 1402092 | AK85: 1586310
A86: 86 | B86: 90 | C86: 0 | D86: 0 | E86: 43503 | F86: 1365639 | G86: 1559987 | H86: 1748668 | U86: 86 | V86: 90 | W86: 0 | X86: 0 | Y86: 54642 | Z86: 1447233 | AA86: 1539795 | AB86: 1663528 | AD86: 86 | AE86: 90 | AF86: 0 | AG86: 0 | AH86: 39631 | AI86: 1173520 | AJ86: 1454779 | AK86: 1630735
A87: 87 | B87: 91 | C87: 0 | D87: 0 | E87: 44780 | F87: 1422084 | G87: 1618092 | H87: 1798439 | U87: 87 | V87: 91 | W87: 0 | X87: 0 | Y87: 56764 | Z87: 1512440 | AA87: 1605542 | AB87: 1724498 | AD87: 87 | AE87: 91 | AF87: 0 | AG87: 0 | AH87: 40763 | AI87: 1224306 | AJ87: 1507967 | AK87: 1676041
A88: 88 | B88: 92 | C88: 0 | D88: 0 | E88: 46003 | F88: 1479405 | G88: 1676972 | H88: 1849167 | U88: 88 | V88: 92 | W88: 0 | X88: 0 | Y88: 58841 | Z88: 1579484 | AA88: 1673091 | AB88: 1787357 | AD88: 88 | AE88: 92 | AF88: 0 | AG88: 0 | AH88: 41848 | AI88: 1275897 | AJ88: 1561816 | AK88: 1722185
A89: 89 | B89: 93 | C89: 0 | D89: 0 | E89: 47163 | F89: 1537824 | G89: 1736895 | H89: 1900780 | U89: 89 | V89: 93 | W89: 0 | X89: 0 | Y89: 60982 | Z89: 1648684 | AA89: 1742778 | AB89: 1852167 | AD89: 89 | AE89: 93 | AF89: 0 | AG89: 0 | AH89: 42875 | AI89: 1328479 | AJ89: 1616573 | AK89: 1769106
A90: 90 | B90: 94 | C90: 0 | D90: 0 | E90: 48338 | F90: 1597791 | G90: 1798367 | H90: 1953282 | U90: 90 | V90: 94 | W90: 0 | X90: 0 | Y90: 63152 | Z90: 1720334 | AA90: 1814913 | AB90: 1918938 | AD90: 90 | AE90: 94 | AF90: 0 | AG90: 0 | AH90: 43927 | AI90: 1382452 | AJ90: 1672725 | AK90: 1816817
A91: 91 | B91: 95 | C91: 0 | D91: 0 | E91: 49450 | F91: 1659979 | G91: 1862154 | H91: 2006567 | U91: 91 | V91: 95 | W91: 0 | X91: 0 | Y91: 65366 | Z91: 1795049 | AA91: 1890142 | AB91: 1987677 | AD91: 91 | AE91: 95 | AF91: 0 | AG91: 0 | AH91: 44931 | AI91: 1438404 | AJ91: 1730991 | AK91: 1865232
... A117: 117 | B117: 121 | C117: 0 | D117: 0 | E117: 348850 | F117: 6620237 | G117: 6838091 | H117: 6838091 | U117: 117 | V117: 121 | W117: 0 | X117: 0 | Y117: 360705 | Z117: 6974617 | AA117: 7074617 | AB117: 7074617 | AD117: 117 | AE117: 121 | AF117: 0 | AG117: 0 | AH117: 318698 | AI117: 5962932 | AJ117: 6278209 | AK117: 6278209
A118: Yr | U118: Yr | AD118: Yr
